Workbook

Sheet Review
A1: ID | B1: Stratum | C1: ⚑ | D1: Question | E1: Reference answer | F1: Alpha's answer | G1: Draft label | H1: Why the draft label | I1: Your label | J1: Draft stale as current | K1: Your stale as current | L1: Your note | M1: Final label | N1: Final stale as current | O1: Retrieval | P1: Quotations Alpha was given | Q1: Evidence in the archive | R1: Expected element | S1: Top 4 retrieved (score)
A2: G-001 | B2: single-fact | D2: How does the run budget estimate how many tokens a run has spent, given that the AI provider doesn't report usage? | E2: It estimates from output length: estimateTokens(text) = ceil(len/4) over the response text; exact usage is deferred and the estimate is an accepted risk. | F2: The run budget estimates token usage by dividing the text length by four and rounding up, as the AI provider does not report actual usage. When estimated spend reaches 80%, the Decider's effort degrades, indicating the run is nearing its token limit. | G2: correct | H2: ceil(len/4) because the provider reports no usage; matches the reference. | I2: correct | M2: =IF(I2="",G2&"",I2) -> correct | N2: =IF(K2="",J2&"",IF(K2="no","",K2)) | O2: hit at rank 1 | P2: Q1 (specs/040-run-budget/design.html, chunk 2 of 3): estimateTokens(text) = ceil(len/4); phase() = halt ≥ 100%, degrade ≥ 80%, else normal (80% = the REQ-FORMAT-004 amber band). Q2 (specs/040-run-budget/design.html, chunk 2 of 3): The AIProvider returns only text (claude.ts:71,131) — no usage to read. Q3 (specs/040-run-budget/spec.html, chunk 2 of 3): A run under a ceiling degrades the Decider effort by one band once estimated spend crosses 80% — observable by the effort passed to the Decider dropping (fewer voters) after the threshold, with the run continuing. | Q2: The AIProvider returns only text ( claude.ts:71,131 ) — no usage to read. Decision estimateTokens(text) = ceil(len/4) ; | R2: specs/040-run-budget/design.html#D-001 | S2: 0.745 specs/040-run-budget/design.html, chunk 2 of 3 0.737 specs/040-run-budget/spec.html, chunk 2 of 3 0.717 specs/040-run-budget/design.html, chunk 1 of 3 0.714 specs/040-run-budget/spec.html, chunk 1 of 3
A3: G-002 | B3: single-fact | D3: How does spectastic add trailers to its automatic commits: does it assemble the commit-message footer itself? | E3: No. run.commit appends one git commit --trailer flag per trailer entry, so git owns RFC-correctness and dedup; this needs git >= 2.32, with interpret-trailers as the fallback. | F3: Spectastic uses one --trailer "k: v" per line to generate a correct footer. The commit-message footer is appended via one --trailer flag per entry, without manual assembly. | G3: correct | H3: One --trailer flag per entry, no hand-built footer. Answered from design chunk 3, a strict retrieval miss. | I3: correct | M3: =IF(I3="",G3&"",I3) -> correct | N3: =IF(K3="",J3&"",IF(K3="no","",K3)) | O3: miss: right file, other chunks | P3: Q1 (specs/027-git-trailers/design.html, chunk 3 of 4): 32): one --trailer "k: v" per line yields a correct footer. run.ts:66 currently passes a single -m. Decision run.commit(subject, trailers) appends one --trailer flag per entry. Q2 (specs/027-git-trailers/design.html, chunk 3 of 4): Decision run.commit(subject, trailers) appends one --trailer flag per entry. No manual footer assembly, no second process. | Q3: Decision run.commit(subject, trailers) appends one --trailer flag per entry. No manual footer assembly, no second process. Consequences + Git owns RFC-correctness + dedup. | R3: specs/027-git-trailers/design.html#D-001 | S3: 0.741 specs/027-git-trailers/design.html, chunk 3 of 4 0.733 specs/027-git-trailers/tasks.html, chunk 2 of 3 0.725 specs/014-core-implement/spec.html, chunk 5 of 5 0.724 specs/031-init-tools/spec.html, chunk 4 of 4
A4: G-003 | B4: single-fact | D4: What made the lines of a wrapped heading overlap when the heading contained inline code? | E4: The h1 line-height of 1.05 was too tight, and inline code's padding, border and 0.9em size made a ~73px box inside a 57px line box; the fix raised h1 line-height to 1.14 and flattened code inside headings. | F4: Not in the archive. | G4: abstained wrongly | H4: The right chunk was retrieved at rank 2, but both of Beta's claims paraphrased and were dropped, so Alpha got no quotations. | I4: abstained wrongly | M4: =IF(I4="",G4&"",I4) -> abstained wrongly | N4: =IF(K4="",J4&"",IF(K4="no","",K4)) | O4: hit at rank 2 | P4: (none) | Q4: root cause was the tight heading line-height:1.05 plus inline code's padding/border/0.9em box exceeding the line box (≈73px vs 57px); fixed in base CSS by loosening h1 line-height to 1.14 | R4: specs/016-theme-support/triage-log.html#T-003 | S4: 0.700 specs/016-theme-support/triage-log.html, chunk 3 of 10 0.676 specs/016-theme-support/triage-log.html, chunk 2 of 10 0.672 specs/016-theme-support/triage-log.html, chunk 8 of 10 0.667 specs/020-vscode-extension/changes/archive/2026-07-10-link-interception/proposal.html, chunk 2 of 2
A5: G-004 | B5: single-fact | D5: In the VS Code extension's canvas, why was the hover card cut off for nodes near the edge of the panel? | E5: The card was appended inside the canvas surface, which the scroll container clips with overflow:auto. The fix renders it on document.body with position:fixed, viewport clamping and flip-above. | F5: The hover card was cut off for nodes near the edge of the panel because the compact card was rendered with position: fixed, which can cause it to be clipped by the scroll container. | G5: wrong | H5: Right chunk at rank 2, but cause and fix are inverted: position:fixed was the fix, not the cause. | I5: wrong | M5: =IF(I5="",G5&"",I5) -> wrong | N5: =IF(K5="",J5&"",IF(K5="no","",K5)) | O5: hit at rank 2 | P5: Q1 (specs/020-vscode-extension/triage-log.html, chunk 1 of 11): Fixed The compact card renders on document.body with position: fixed in packages/vscode/src/webview/card.ts, escaping the scroll container’s clip. | Q5: root cause was implementation drift — the card was appended inside the canvas surface, which the scroll container clips with overflow:auto ; fixed by rendering it on <body> with position:fixed , viewport clamping, and flip-above; | R5: specs/020-vscode-extension/triage-log.html#T-002 | S5: 0.737 specs/020-vscode-extension/design.html, chunk 1 of 6 0.736 specs/020-vscode-extension/triage-log.html, chunk 1 of 11 0.734 specs/020-vscode-extension/spec.html, chunk 2 of 5 0.724 specs/020-vscode-extension/changes/archive/2026-06-22-vertical-layout-default/proposal.html, chunk 1 of 3
A6: G-005 | B6: single-fact | D6: Does init --tools wire spectastic enforce into the pre-commit hook it installs? | E6: Not automatically. That integration was deferred because 031's hook uses exec, so you wire it manually (spectastic enforce || exit 1), and FR-005 is only partially met. | F6: spectastic init --tools installs a git pre-commit gate that rejects a commit when spectastic validate finds an error. spectastic init --tools also installs the Claude Code command adapters. | G6: wrong | H6: Describes the validate gate the hook installs; never says enforce is not wired in. | M6: =IF(I6="",G6&"",I6) -> wrong | N6: =IF(K6="",J6&"",IF(K6="no","",K6)) | O6: miss: another spec | P6: Q1 (specs/031-init-tools/spec.html, chunk 1 of 4): spectastic init --tools is that mechanism: it installs a git pre-commit gate that rejects a commit when spectastic validate finds an error (or an open question in an Accepted spec), and it installs the Claude Code command adapters so they cannot drift from source. Q2 (specs/031-init-tools/spec.html, chunk 4 of 4): After init --tools, editing a commands/*.md source is reflected in the installed Claude Code adapter with no manual copy step, and an installed adapter is never observed stale against its source. | Q6: 031's hook uses exec , so appending enforce needs an opt-in flag threaded through tested code. The enforce command is delivered and CI/hook-ready — wire it manually ( spectastic enforce || exit 1 ); | R6: specs/042-profile-enforcement/tasks.html#T-901 | S6: 0.804 specs/031-init-tools/spec.html, chunk 4 of 4 0.770 specs/031-init-tools/spec.html, chunk 1 of 4 0.765 specs/031-init-tools/tasks.html, chunk 1 of 2 0.755 specs/031-init-tools/spec.html, chunk 2 of 4
A7: G-006 | B7: single-fact | D7: Why did the npm publish of v0.1.0-pre.28 fail? | E7: It was a credential failure, not a code one: the npm step returned 404 Not Found on the PUT for @spectastic/render, which points to NPM_TOKEN expiring, rotating or losing scope. The fix moved publishing to OIDC trusted publishing. | F7: The v0.1.0-pre.28 publish failed with a 404 Not Found error, indicating a credential failure at the npm step. The timing of the failure suggests the NPM_TOKEN may have expired, rotated, or lost scope. npm is phasing out 2FA-bypass tokens for direct publishing, which may have impacted the token’s validity. | G7: correct | H7: 404 on the npm PUT, a credential failure, token expired or rotated. | M7: =IF(I7="",G7&"",I7) -> correct | N7: =IF(K7="",J7&"",IF(K7="no","",K7)) | O7: hit at rank 1 | P7: Q1 (specs/004-npm-publish-workflow/changes/archive/2026-09-14-oidc-trusted-publishing/proposal.html, chunk 1 of 6): The v0.1.0-pre.28 publish failed twice at the npm step with 404 Not Found - PUT …/@spectastic%2frender — a credential failure, not a code one (every gate passed). Q2 (specs/004-npm-publish-workflow/changes/archive/2026-09-14-oidc-trusted-publishing/proposal.html, chunk 1 of 6): The same-night pattern (pre.27 published at 00:14, pre.28 failed at 02:39) points at the NPM_TOKEN expiring, rotating, or losing scope. Q3 (specs/004-npm-publish-workflow/changes/archive/2026-09-14-oidc-trusted-publishing/proposal.html, chunk 1 of 6): npm is deprecating 2FA-bypass granular tokens for direct publishing — Phase 2 (~Jan 2027) restricts them to staged publishes needing human approval — so a token-based flow is on a clock regardless. | Q7: The v0.1.0-pre.28 publish failed twice at the npm step with 404 Not Found - PUT …/@spectastic%2frender — a credential failure, not a code one (every gate passed). | R7: specs/004-npm-publish-workflow/changes/archive/2026-09-14-oidc-trusted-publishing/proposal.html#intent | S7: 0.725 specs/004-npm-publish-workflow/changes/archive/2026-09-14-oidc-trusted-publishing/proposal.html, chunk 1 of 6 0.721 specs/004-npm-publish-workflow/triage-log.html, chunk 1 of 2 0.720 specs/004-npm-publish-workflow/changes/archive/2026-07-23-prerelease-latest-dist-tag/proposal.html, chunk 1 of 5 0.718 specs/004-npm-publish-workflow/design.html, chunk 1 of 5
A8: G-007 | B8: single-fact | D8: Does the published web address for spectastic's config JSON schema actually resolve yet? | E8: No. Fetching it at the pinned version returns 404 because the currently published version predates the schema file, so the check is to be repeated at the next release. | F8: Not in the archive. | G8: abstained wrongly | H8: 087 tasks.html chunk 2 was retrieved; Beta's only claim paraphrased and was dropped. | M8: =IF(I8="",G8&"",I8) -> abstained wrongly | N8: =IF(K8="",J8&"",IF(K8="no","",K8)) | O8: miss: right file, other chunks | P8: (none) | Q8: Deliberately unticked: it returns 404 today, because the currently-published version predates the schema file. Repeat at the next release | R8: specs/087-config-published-schema/tasks.html#T-301 | S8: 0.711 specs/063-corpus-discoverability/spec.html, chunk 4 of 4 0.710 specs/087-config-published-schema/tasks.html, chunk 2 of 2 0.704 specs/057-portable-domain-skill/design.html, chunk 3 of 6 0.701 specs/119-decision-resource-scope/design.html, chunk 2 of 5
A9: G-008 | B9: single-fact | C9: ⚑ | D9: When the kernel was extracted, what benchmark baseline was full-project validation expected to stay within 20% of? | E9: The validate-full-project p50 should stay within ±20% of 175 ms on an M1 dev machine and 295 ms on ubuntu-latest CI. | F9: The full-project validation was expected to stay within 20% of a 175 ms baseline. | G9: partly | H9: Gives the 175 ms M1 baseline; misses the 295 ms CI figure. | I9: partly | M9: =IF(I9="",G9&"",I9) -> partly | N9: =IF(K9="",J9&"",IF(K9="no","",K9)) | O9: miss: right file, other chunks | P9: Q1 (specs/006-kernel-extraction/spec.html, chunk 6 of 6): bench all 4 scenarios within budget (validate-full-project p50 184 ms vs 175 ms baseline = +5%, well inside NFR-002's ±20% target) | Q9: The validate-full-project bench scenario's p50 SHOULD stay within ±20% of today's baseline (175 ms on M1 dev; 295 ms on ubuntu-latest CI). | R9: specs/006-kernel-extraction/spec.html#NFR-002 | S9: 0.788 specs/006-kernel-extraction/spec.html, chunk 6 of 6 0.738 specs/006-kernel-extraction/design.html, chunk 1 of 5 0.735 specs/006-kernel-extraction/spec.html, chunk 2 of 6 0.721 specs/006-kernel-extraction/spec.html, chunk 1 of 6
A10: G-009 | B10: single-fact | C10: ⚑ | D10: In the change-risk verification run, what result did a diff with a staged binary plus a CI workflow edit produce? | E10: Two findings, a 55/100 amber score and the disclaimer, with exit code 0. | F10: A diff with a staged binary plus a CI workflow edit produced two findings, a score, a band, and the 'surfaces risk, not detection' disclaimer. | G10: partly | H10: Two findings and the disclaimer; misses the 55/100 amber score and exit code 0. Quoted tasks.html, not the verify run. | I10: partly | L10: the correct answer was ranked higher so seems selection needs adjustment. | M10: =IF(I10="",G10&"",I10) -> partly | N10: =IF(K10="",J10&"",IF(K10="no","",K10)) | O10: hit at rank 1 | P10: Q1 (specs/049-change-risk-score/tasks.html, chunk 2 of 3): packages/core/test/change-risk.score.test.ts Test the CLI end-to-end on a fixture repo — a binary+CI-edit diff prints two findings, a score, a band, and the "surfaces risk, not detection" disclaimer (FR-001, SC-001); | Q10: (1) a staged binary + CI-workflow edit prints two findings, a 55/100 amber score, and the disclaimer, exit 0; | R10: specs/049-change-risk-score/verify.html#run | S10: 0.727 specs/049-change-risk-score/verify.html, chunk 1 of 1 0.723 specs/049-change-risk-score/tasks.html, chunk 2 of 3 0.706 specs/049-change-risk-score/spec.html, chunk 1 of 3 0.688 specs/049-change-risk-score/design.html, chunk 1 of 5
A11: G-010 | B11: single-fact | D11: Why does triage fan-out use a hand-rolled concurrency pool instead of the p-map library? | E11: p-map is only a dev/CI transitive dependency, and promoting it would add a real runtime dependency to the published package. The owner kept @spectastic/core dependency-minimal, so a ~30-line mapPool copies p-map's input-order and concurrency-cap semantics. | F11: The serial list loop is the bottleneck to replace packages/core/src/commands/triage.ts:67 verified for (const item of items) { await characterise(…) } — one blocking call per item. The hedge gate is inline mid-loop — must move to a post-pass triage.ts:100-103, 117-159 verified escalateLayer calls ai.ask inside characterise; can't interleave under concurrency (FR-005). IDs are assigned interleaved in loop order — must become one post-pass triage. | G11: wrong | H11: Talks about the serial loop bottleneck; never says why p-map was not used. | M11: =IF(I11="",G11&"",I11) -> wrong | N11: =IF(K11="",J11&"",IF(K11="no","",K11)) | O11: miss: right file, other chunks | P11: Q1 (specs/032-triage-fanout/design.html, chunk 1 of 5): The serial list loop is the bottleneck to replace packages/core/src/commands/triage.ts:67 verified for (const item of items) { await characterise(…) } — one blocking call per item. Q2 (specs/032-triage-fanout/design.html, chunk 1 of 5): The hedge gate is inline mid-loop — must move to a post-pass triage.ts:100-103, 117-159 verified escalateLayer calls ai.ask inside characterise; can't interleave under concurrency (FR-005). Q3 (specs/032-triage-fanout/design.html, chunk 1 of 5): IDs are assigned interleaved in loop order — must become one post-pass triage. | Q11: p-map@7.0.4 is the obvious library but is only a dev/CI transitive via @secretlint/node ( pnpm-lock.yaml:2597 ) — promoting it adds a real runtime dep to the published package. | R11: specs/032-triage-fanout/design.html#D-002 | S11: 0.752 specs/032-triage-fanout/design.html, chunk 1 of 5 0.750 specs/032-triage-fanout/changes/archive/2026-07-10-interactive-fanout/proposal.html, chunk 1 of 2 0.736 specs/032-triage-fanout/spec.html, chunk 1 of 4 0.727 specs/032-triage-fanout/triage-log.html, chunk 1 of 2
A12: G-011 | B12: paraphrase | D12: Why does a design page bake in a duplicate of the API definition's text instead of pulling that file in live while someone is viewing it? | E12: The artifact's Content-Security-Policy (default-src 'none', no connect-src) blocks a runtime fetch, and an iframe would be flagged by the no-executable-content rule, so the contract text is copied in at generate time and drift is guarded separately. | F12: The design page bakes in a duplicate of the API definition's text because the materialiser reads the file, escapes it, and emits it as part of the declaration. This approach was chosen to avoid runtime fetches, which are blocked by the default-src policy and the no-executable-content rule. The outbound pipeline ensures that the content is fully processed and written to a dated path before the browser opens the file, making byte-identity a property of the code. | G12: correct | H12: CSP default-src blocks a runtime fetch and the no-executable-content rule rules out the alternative. Strict retrieval miss. | M12: =IF(I12="",G12&"",I12) -> correct | N12: =IF(K12="",J12&"",IF(K12="no","",K12)) | O12: miss: right file, other chunks | P12: Q1 (specs/072-contract-embedded-view/design.html, chunk 3 of 6): 5 · Approach At design-generation time, for each declaration carrying a readable path=, the materialiser reads the file, escapes it with the existing esc(), truncates it to a line budget if needed, and emits a <spec-contract-view> nested inside the declaration. Q2 (specs/072-contract-embedded-view/design.html, chunk 3 of 6): 7 · Decisions D-001 · Materialise at generate time; never transclude Status Accepted Context templates/design.html:6 sets default-src 'none' with no connect-src, so a runtime fetch is blocked by policy; <iframe> is separately flagged by the no-executable-content rule. The content must therefore be present in the file before the browser opens it. Q3 (specs/107-visual-design-brief/design.html, chunk 3 of 7): 6 · Approach Two capabilities that share one fact and nothing else. Outbound is a three-step pipeline with I/O only at the ends: a reader walks the feature’s declared screens and returns a complete model (every state, every refusal, every annotation, the addressed contexts), a renderer turns that model into Markdown, and a write puts it at a dated path. Nothing in the middle touches a filesystem, a clock or a network, which is what makes NFR-002’s byte-identity a property of the code rather than a hope. | Q12: templates/design.html:6 sets default-src 'none' with no connect-src , so a runtime fetch is blocked by policy; <iframe> is separately flagged by the no-executable-content rule. | R12: specs/072-contract-embedded-view/design.html#D-001 | S12: 0.678 specs/072-contract-embedded-view/design.html, chunk 3 of 6 0.678 specs/000-spectastic/triage-log.html, chunk 21 of 39 0.672 specs/107-visual-design-brief/design.html, chunk 3 of 7 0.665 specs/012-core-plan/spec.html, chunk 4 of 5
A13: G-012 | B13: paraphrase | D13: If someone tweaks a file that came in from a design tool and later brings in a fresh version from that tool, are their tweaks kept? | E13: Yes, manual changes survive a re-import, except on fields whose source of truth is the export; those fields are re-derived on every import. | F13: An installed adapter must be structurally impossible to drift from its source. The installed hook is intended to be portable across macOS and Linux shells. | G13: wrong | H13: Answers about installed adapters drifting, from 031; nothing about re-imports. | M13: =IF(I13="",G13&"",I13) -> wrong | N13: =IF(K13="",J13&"",IF(K13="no","",K13)) | O13: miss: right file, other chunks | P13: Q1 (specs/031-init-tools/spec.html, chunk 3 of 4): md source such that an installed adapter cannot drift from its source — a stale installed copy MUST be structurally impossible (generated or linked on demand, not a one-time copy). Q2 (specs/031-init-tools/spec.html, chunk 3 of 4): The installed hook SHOULD be portable across the macOS and Linux shells spectastic targets; Windows support is deferred. | Q13: A hand edit to landed material MUST survive a re-import, except where the field has a source of truth in the export. | R13: specs/105-design-source-import/spec.html#FR-009 specs/105-design-source-import/design.html#D-002 | S13: 0.713 specs/031-init-tools/spec.html, chunk 3 of 4 0.708 specs/105-design-source-import/triage-log.html, chunk 2 of 18 0.707 specs/105-design-source-import/spec.html, chunk 9 of 11 0.706 specs/105-design-source-import/changes/archive/2026-08-18-what-the-design-tool-is/proposal.html, chunk 1 of 5
A14: G-013 | B14: paraphrase | C14: ⚑ | D14: How does the prose theme make sure its fade-in-on-scroll effect can never leave text invisible if the page's code fails to load or errors out? | E14: The stylesheet never hides anything. The script marks the document as reveal-capable when it runs, and only then does the hidden state exist, so a failure degrades to plain visible content. | F14: The prose theme ensures fully readable artifacts even with JavaScript disabled, preventing text from being invisible due to code failures. The reveal mechanism is designed as a progressive enhancement, requiring no markup changes and ensuring blocks are revealed exactly once, regardless of script errors. | G14: partly | H14: Progressive enhancement and readable with JavaScript off, but not the mechanism (the script marks the document reveal-capable). | M14: =IF(I14="",G14&"",I14) -> partly | N14: =IF(K14="",J14&"",IF(K14="no","",K14)) | O14: miss: right file, other chunks | P14: Q1 (specs/109-prose-theme/spec.html, chunk 3 of 5): With JavaScript disabled, an artifact MUST render fully readable, and with reduced motion requested the reveal MUST be suppressed entirely, leaving at most 0 blocks hidden from the reader in either case. Q2 (specs/109-prose-theme/spec.html, chunk 3 of 5): The reveal and the header's scroll-up trigger MUST be implemented as a progressive enhancement in the shared switcher script, latching each block to revealed exactly once; they MUST take effect only while Prose is the active theme, and MUST require at most 0 markup changes to any document. | Q14: The stylesheet never hides a block. The script marks the document as reveal-capable when it runs, and only then does the unrevealed state exist. | R14: specs/109-prose-theme/design.html#D-003 | S14: 0.769 specs/109-prose-theme/spec.html, chunk 3 of 5 0.746 specs/109-prose-theme/design.html, chunk 1 of 7 0.744 specs/016-theme-support/changes/archive/2026-08-19-amend-theme-contract-for-prose/proposal.html, chunk 1 of 5 0.744 specs/109-prose-theme/spec.html, chunk 2 of 5
A15: G-014 | B15: paraphrase | D15: Once a project's knowledge base outgrows simple lookup, which search upgrades should be layered on, in what sequence, and how much does each one help? | E15: Contextual embeddings, then contextual BM25, then reranking, in that order. They cut retrieval failures by roughly a third, a half and two-thirds respectively. | F15: When a project's knowledge base outgrows simple lookup, re-ordering requirements is the first step to manage task renumbering and amendments. Light AI integration follows re-ordering, providing structured one-liner outputs for imperative tasks while delegating structural work to prior phases. Traceability mechanisms, such as spec-notes and warnings, are layered last to ensure all requirements are referenced and uncovered gaps are flagged. | G15: wrong | H15: Answers about re-ordering requirements, from 009; the ladder in 059 FR-002 was never retrieved. | M15: =IF(I15="",G15&"",I15) -> wrong | N15: =IF(K15="",J15&"",IF(K15="no","",K15)) | O15: miss: another spec | P15: Q1 (specs/009-core-tasks/design.html, chunk 3 of 4): − Re-ordering requirements renumbers tasks (the future implement verb's checked-state merge handles amendments, deferred). − ≥4 stories overflow into T-4NN+ with a warning. Q2 (specs/009-core-tasks/design.html, chunk 3 of 4): D-004 · Light AI — one ctx.ai.chat() per non-empty phase Status Accepted Context D-002 / D-003 do the structural work; AI only writes the imperative one-liner + optional target path. Q3 (specs/009-core-tasks/design.html, chunk 3 of 4): D-005 · Traceability — <spec-note> per US phase + <spec-warning> for uncovered Status Accepted Context FR-008 requires every FR/NFR/SC to be referenced by ≥1 task; uncovered → warning. | Q15: retrieval SHOULD follow the known ladder — contextual embeddings, then contextual BM25, then reranking — in that order. Rationale The ladder is characterised: the three stages cut retrieval failures by roughly a third, a half, and two-thirds respectively. | R15: specs/059-corpus-retrieval-scale/spec.html#FR-002 | S15: 0.694 specs/009-core-tasks/design.html, chunk 3 of 4 0.688 specs/047-slo-nfr-artifact/tasks.html, chunk 4 of 4 0.684 specs/024-explore-restore/tasks.html, chunk 1 of 2 0.683 specs/089-lifecycle-contract/spec.html, chunk 7 of 7
A16: G-015 | B16: paraphrase | C16: ⚑ | D16: Will validation stop me from checking in a reference book whose terms forbid sharing it? | E16: No. A redistribution-restricted document raises a corpus-license finding at warning severity, not an error, because committing it is the project's call; the rule only makes the fact visible. | F16: Validation will not stop you from checking in a reference book whose terms forbid sharing it. The redistribution policy specifies that material that cannot be redistributed may be held by reference, with a sanctioned escape hatch for such cases. | G16: correct | H16: Validation will not stop the commit; misses that it is a warning-severity finding. | M16: =IF(I16="",G16&"",I16) -> correct | N16: =IF(K16="",J16&"",IF(K16="no","",K16)) | O16: miss: right spec, other pages | P16: Q1 (specs/058-corpus-licensing/design.html, chunk 3 of 6): The rule reads only the declared string; it never infers a license from content and never asserts legal compatibility (NFR-001, the recorded ceiling). Q2 (specs/058-corpus-licensing/design.html, chunk 3 of 6): A declared license is silent only if it's on the permissive allowlist; restrictive, unrecognised, and placeholder licenses all warn. Q3 (specs/058-corpus-licensing/design.html, chunk 3 of 6): The redistribution policy (FR-003/FR-004) is a README section: what may be committed in-repo, what must be held by reference, and the sanctioned by-reference escape hatch (an MCP bridge, or keeping only the origin-url) for material that cannot be redistributed — with the deliberately-restrictive KB-002 described as the worked example. | Q16: A warning, not an error: whether to commit restricted material is a project's call to make with the fact in front of it. The rule's job is to make the fact unavoidable, not to block the decision. | R16: specs/058-corpus-licensing/spec.html#FR-002 | S16: 0.699 specs/002-validate-cli/spec.html, chunk 3 of 5 0.696 specs/052-corpus-citation-contract/design.html, chunk 2 of 6 0.694 specs/058-corpus-licensing/design.html, chunk 3 of 6 0.690 specs/108-success-criteria/spec.html, chunk 5 of 6
A17: G-016 | B17: paraphrase | D17: Is it acceptable for a success criterion to require that something never happens, or always happens, without giving any reasoning? | E17: No. A criterion asserting a threshold of 0 or 100% (or two equal thresholds) must carry a stated justification, because a bare absolute is often an unfalsifiable reflex. | F17: A success criterion must define two thresholds: a failure level and an aspiration level. The structure of a criterion is critical; it cannot be implied or assumed, as no check reads or owns its shape. | G17: wrong | H17: Talks about failure and aspiration thresholds; misses the justification rule for 0 or 100%. | M17: =IF(I17="",G17&"",I17) -> wrong | N17: =IF(K17="",J17&"",IF(K17="no","",K17)) | O17: miss: right file, other chunks | P17: Q1 (specs/108-success-criteria/spec.html, chunk 2 of 6): A criterion MUST state two thresholds: the level below which the feature has failed, and the level it is aiming at. Q2 (specs/108-success-criteria/spec.html, chunk 1 of 6): The cause is structural rather than careless: no requirement anywhere owns the shape of a criterion and no check reads one — the whole contract is two sentences of command markdown, which is the one place this project already says a guarantee may not live. | Q17: A criterion asserting a threshold of 0 or 100%, or two equal thresholds, MUST carry a stated justification. | R17: specs/108-success-criteria/spec.html#FR-011 | S17: 0.765 specs/108-success-criteria/spec.html, chunk 1 of 6 0.710 specs/108-success-criteria/spec.html, chunk 2 of 6 0.704 specs/108-success-criteria/tasks.html, chunk 1 of 4 0.689 specs/090-command-surface/changes/archive/2026-08-20-triage-dispatch-and-ids/proposal.html, chunk 4 of 6
A18: G-017 | B18: paraphrase | D18: If the one-step visual flow is given a path to a design handoff that it can't open, how far does it get before giving up? | E18: It refuses straight away, before any model call or any file write, and names the path it could not read. | F18: The one-step visual flow is designed to exit immediately upon encountering an unopenable path, as all visual actions currently end in process.exit(). If the path to a design handoff is unreadable, the one-step visual flow will not attempt to call any model or write any files, effectively giving up without further action. | G18: correct | H18: Refuses before any model call or file write. Strict retrieval miss. | M18: =IF(I18="",G18&"",I18) -> correct | N18: =IF(K18="",J18&"",IF(K18="no","",K18)) | O18: miss: right file, other chunks | P18: Q1 (specs/110-visual-one-step/design.html, chunk 1 of 7): The biggest risk is not the wiring: it is that all four visual actions currently end in process.exit(), so each has to be split into a callable kernel and a thin exiting wrapper before anything can call them. Q2 (specs/110-visual-one-step/spec.html, chunk 4 of 6): Authors who mistype an export path lose nothing — model calls made = 0 and files written = 0 on a run naming an unreadable export, from a design generation’s full cost today. | Q18: Before making any model call and before writing any file, the invocation MUST refuse when the named export cannot be read, and MUST state which path it could not read. | R18: specs/110-visual-one-step/spec.html#FR-003 | S18: 0.727 specs/110-visual-one-step/design.html, chunk 1 of 7 0.726 specs/110-visual-one-step/spec.html, chunk 1 of 6 0.724 specs/110-visual-one-step/spec.html, chunk 4 of 6 0.721 specs/110-visual-one-step/tasks.html, chunk 1 of 5
A19: G-018 | B19: paraphrase | C19: ⚑ | D19: What performance problem pushed the project to break its flagship specification document into several smaller ones? | E19: At 118 KB the meta-spec took about 140 ms to validate on CI (about 28 ms locally) against a 100 ms per-file budget, so the project failed its own performance requirement. | F19: The meta-spec breached its own NFR-001 validation budget on continuous integration hardware. The size gauge showed a consistent red status, indicating it exceeded the 5,000-word budget. The lifecycle provided a mechanism for splitting the document, which was followed. | G19: correct | H19: The meta-spec breached its own validation budget on CI; no figures. | M19: =IF(I19="",G19&"",I19) -> correct | N19: =IF(K19="",J19&"",IF(K19="no","",K19)) | O19: hit at rank 1 | P19: Q1 (specs/000-spectastic/changes/archive/2026-08-11-extract-five-slices/proposal.html, chunk 1 of 5): The meta-spec is 118 KB and breaches its own NFR-001 validation budget on continuous integration hardware, and its size gauge has been red for some time. Q2 (specs/000-spectastic/changes/archive/2026-08-11-extract-five-slices/proposal.html, chunk 1 of 5): Its size gauge tells the same story in the header of every render: 9,638 words against a 5,000 budget, 39 requirements against 20, banded red with the tool's own advice to split. Q3 (specs/000-spectastic/changes/archive/2026-08-11-extract-five-slices/proposal.html, chunk 1 of 5): The advice is right, and this is the mechanism the lifecycle already provides for taking it. | Q19: At 118 KB the meta-spec takes about 28 ms to validate on a developer machine and roughly 140 ms on a continuous-integration runner, against a budget of 100 ms per file | R19: specs/000-spectastic/changes/archive/2026-08-11-extract-five-slices/proposal.html#intent | S19: 0.705 specs/000-spectastic/changes/archive/2026-08-11-extract-five-slices/proposal.html, chunk 1 of 5 0.676 specs/110-visual-one-step/design.html, chunk 7 of 7 0.672 specs/000-spectastic/triage-log.html, chunk 2 of 39 0.672 specs/011-core-spec/design.html, chunk 4 of 5
A20: G-019 | B20: paraphrase | D20: Why did the auto-generated verification pages scroll sideways on a narrow phone screen, and how was it fixed? | E20: renderVerifyHtml emitted the trace and observables tables with no scroll container. Both tables are now wrapped in an overflow-x:auto container where they are emitted. | F20: The auto-generated verification pages scrolled sideways on a narrow phone screen because the tables were not wrapped in an overflow container. The issue was fixed by modifying the renderVerifyHtml function to enclose both tables within an overflow-x:auto container. | G20: correct | H20: Tables had no overflow container; renderVerifyHtml now wraps both in overflow-x:auto. Strict retrieval miss. | M20: =IF(I20="",G20&"",I20) -> correct | N20: =IF(K20="",J20&"",IF(K20="no","",K20)) | O20: miss: right file, other chunks | P20: Q1 (specs/021-verify-view/triage-log.html, chunk 4 of 5): scrolls its tables inside their own container at a narrow viewport, as the hand-authored artifacts do. Actual 2 bare <table> elements and 0 wrappers in every one of the 70 generated views. Q2 (specs/021-verify-view/triage-log.html, chunk 4 of 5): Fix Done. packages/core/src/commands/verify.ts — both tables now emit inside an overflow-x:auto container in renderVerifyHtml. | Q20: root cause was renderVerifyHtml emitting the trace and observables tables with no scroll container; fixed by wrapping them at the point of emission; | R20: specs/021-verify-view/triage-log.html#T-004 | S20: 0.672 specs/021-verify-view/triage-log.html, chunk 4 of 5 0.640 specs/094-visual-sidecar-convention/spec.html, chunk 4 of 4 0.638 specs/021-verify-view/triage-log.html, chunk 5 of 5 0.636 specs/048-verify-slo-trace/tasks.html, chunk 3 of 3
A21: G-020 | B21: paraphrase | D21: In a generated course, learners had nowhere to type their own explanation of an idea. What was wrong, and what changed? | E21: The implementation rendered the teach-back prompt as static prose with no input. It now renders a textarea under the prompt, labelled as not saved, because course content isn't persisted. | F21: The issue was that the course lacked a <textarea> element for learners to input their own explanations. The change involved modifying the 'course.ts' file to include a <textarea> under the teach-back prompt. | G21: correct | H21: Static prompt with no input; a textarea added under the teach-back prompt. | M21: =IF(I21="",G21&"",I21) -> correct | N21: =IF(K21="",J21&"",IF(K21="no","",K21)) | O21: hit at rank 3 | P21: Q1 (specs/019-explain-course/triage-log.html, chunk 1 of 5): Fix packages/core/src/commands/course.ts — render a <textarea> under the teach-back prompt. | Q21: root cause was the implementation rendering the prompt as static prose with no input; fixed by adding a non-persisted <textarea> ; | R21: specs/019-explain-course/triage-log.html#T-002 | S21: 0.740 specs/019-explain-course/spec.html, chunk 3 of 4 0.718 specs/019-explain-course/changes/archive/2026-08-12-answer-position/proposal.html, chunk 1 of 2 0.717 specs/019-explain-course/triage-log.html, chunk 1 of 5 0.715 specs/012-core-plan/changes/archive/2026-08-23-preserve-what-the-generator-does-not-emit/proposal.html, chunk 2 of 5
A22: G-021 | B22: identifier | D22: What does FR-001 of spec 040, the run budget, require of the BudgetTracker? | E22: It must accumulate the run's estimated output-token spend and expose a phase: normal below 80% of the ceiling, degrade at >=80%, halt at >=100% (always normal when there is no ceiling). | F22: FR-001 of spec 040, the run budget, requires the BudgetTracker to accumulate the run's estimated output-token spend and expose its phase: normal below 80% of the ceiling, degrade at ≥ 80%, halt at ≥ 100%. With no ceiling it is always normal. When the tracker is in degrade, the run MUST lower the effort it passes to the Decider by one band (via the 034 effort order), clamped at the floor — so decisions convene fewer voters. | G22: correct | H22: Accumulate estimated spend; normal, degrade at 80%, halt at 100%. | M22: =IF(I22="",G22&"",I22) -> correct | N22: =IF(K22="",J22&"",IF(K22="no","",K22)) | O22: hit at rank 4 | P22: Q1 (specs/040-run-budget/spec.html, chunk 2 of 3): Functional A BudgetTracker MUST accumulate the run's estimated output-token spend and expose its phase: normal below 80% of the ceiling, degrade at ≥ 80%, halt at ≥ 100%. With no ceiling it is always normal. Q2 (specs/040-run-budget/spec.html, chunk 2 of 3): When the tracker is in degrade, the run MUST lower the effort it passes to the Decider by one band (via the 034 effort order), clamped at the floor — so decisions convene fewer voters. | Q22: A BudgetTracker MUST accumulate the run's estimated output-token spend and expose its phase : normal below 80% of the ceiling, degrade at ≥ 80%, halt at ≥ 100%. | R22: specs/040-run-budget/spec.html#FR-001 | S22: 0.702 specs/040-run-budget/verify.html, chunk 1 of 1 0.691 specs/040-run-budget/design.html, chunk 1 of 3 0.678 specs/040-run-budget/tasks.html, chunk 1 of 1 0.651 specs/040-run-budget/spec.html, chunk 2 of 3
A23: G-022 | B23: identifier | D23: What does NFR-001 in spec 045, artifact security, require? | E23: FR-001 and FR-002 must be deterministic and must not break the rendering or interactivity of any existing spec-family artifact type, verified by opening representative artifacts in a browser. | F23: NFR-001 in spec 045, artifact security, requires verification. An unquantified NFR fails at the tiers that promise reliability. | G23: wrong | H23: Says NFR-001 requires verification; the requirement is determinism and not breaking existing artifacts. | M23: =IF(I23="",G23&"",I23) -> wrong | N23: =IF(K23="",J23&"",IF(K23="no","",K23)) | O23: miss: right spec, other pages | P23: Q1 (specs/045-artifact-security/verify.html, chunk 1 of 1): NFR-001 n/a NFR-002 n/a Verify · 045-artifact-security · derived view · light/dark Q2 (specs/047-slo-nfr-artifact/spec.html, chunk 1 of 4): Specification · 047-slo-nfr-artifact SLO-from-NFR artifact model A quantified NFR is an SLO in prose. This gives that SLO a first-class shape linked to its NFR — and makes an unquantified NFR fail at the tiers that promise reliability. | Q23: FR-001 and FR-002 MUST be deterministic and MUST NOT break the rendering or interactivity of any existing spec-family artifact type | R23: specs/045-artifact-security/spec.html#NFR-001 | S23: 0.711 specs/045-artifact-security/verify.html, chunk 1 of 1 0.708 specs/047-slo-nfr-artifact/spec.html, chunk 1 of 4 0.704 specs/047-slo-nfr-artifact/changes/archive/2026-07-29-quantified-nfr-convention-floor/proposal.html, chunk 1 of 3 0.701 specs/047-slo-nfr-artifact/design.html, chunk 1 of 4
A24: G-023 | B24: identifier | D24: What does success criterion SC-002 of spec 119, decision resource scope, measure? | E24: That a reviewer in a consuming service is flagged, at the decision's declared posture, when their change touches a store owned elsewhere, in both the direct-write and own-adapter cases: 2 of 2 non-owner fixture scenarios (C and D) must flag. | F24: Not in the archive. | G24: abstained wrongly | H24: Beta's only claim paraphrased and was dropped; the expected element was not retrieved either. | M24: =IF(I24="",G24&"",I24) -> abstained wrongly | N24: =IF(K24="",J24&"",IF(K24="no","",K24)) | O24: miss: right spec, other pages | P24: (none) | Q24: A reviewer in a consuming service is flagged, at the decision's declared posture, when their change touches a store owned elsewhere — in both the direct-write and the well-layered-own-adapter case: 2 of 2 non-owner fixture scenarios flag | R24: specs/119-decision-resource-scope/spec.html#SC-002 | S24: 0.761 specs/119-decision-resource-scope/design.html, chunk 1 of 5 0.744 specs/119-decision-resource-scope/verify.html, chunk 1 of 1 0.739 specs/119-decision-resource-scope/tasks.html, chunk 1 of 2 0.711 specs/108-success-criteria/spec.html, chunk 1 of 6
A25: G-024 | B25: identifier | C25: ⚑ | D25: In the design for spec 026, git strategy, what does decision D-002 settle about where configuration lives? | E25: Config lives in a root spectastic.json with a git section ({"git": {"auto": "off"}}); an absent file or key falls back to defaults (auto=off), chosen over a hidden .spectastic/ directory. | F25: Decision D-002 settles that configuration lives in a file named spectastic.json at the project root. | G25: correct | H25: spectastic.json at the project root; misses the git section and the defaults. | M25: =IF(I25="",G25&"",I25) -> correct | N25: =IF(K25="",J25&"",IF(K25="no","",K25)) | O25: miss: right file, other chunks | P25: Q1 (specs/026-git-strategy/design.html, chunk 1 of 5): Storage New spectastic.json at project root, one git section; absent file → all keys default (D-002). | Q25: Read a root spectastic.json with a git section ( { "git": { "auto": "off" } } ); absent file or key → defaults ( auto=off ). | R25: specs/026-git-strategy/design.html#D-002 | S25: 0.753 specs/026-git-strategy/design.html, chunk 1 of 5 0.710 specs/026-git-strategy/spec.html, chunk 1 of 4 0.708 specs/026-git-strategy/verify.html, chunk 1 of 1 0.693 specs/026-git-strategy/spec.html, chunk 4 of 4
A26: G-025 | B26: identifier | D26: What is task T-100 in the task list for spec 065, corpus PDF convert? | E26: Write a failing test that the default convert path (MarkItDown), with the stub runner and fixture shim, reaches the same terminal pack state as an equivalent adaptCorpus call, in packages/corpus/test/knowledge.convert.test.ts. | F26: Task T-100 is part of the task list for spec 065, corpus PDF convert, and is described as 'document conversion into the corpus'. Task numbering follows the spec's pattern, with T-1xx corresponding to US1. | G26: wrong | H26: Describes T-100 generically ('document conversion'); not the failing-test task it is. | M26: =IF(I26="",G26&"",I26) -> wrong | N26: =IF(K26="",J26&"",IF(K26="no","",K26)) | O26: miss: right file, other chunks | P26: Q1 (specs/065-corpus-pdf-convert/tasks.html, chunk 1 of 3): Tasks · 065-corpus-pdf-convert corpus convert — document conversion into the corpus Ordered, parallelizable work. Tests precede implementation. Drive through with /spectastic.implement — one task per invocation. Q2 (specs/065-corpus-pdf-convert/tasks.html, chunk 1 of 3): 1 · Execution strategy Story IDs follow the spec's numbering (T-1xx = US1, T-2xx = US2, T-3xx = US3) regardless of build order. | Q26: Write failing test: default convert files a doc — with the stub runner + fixture shim, the default (MarkItDown) path reaches the same terminal pack state as an equivalent adaptCorpus call. | R26: specs/065-corpus-pdf-convert/tasks.html#T-100 | S26: 0.788 specs/065-corpus-pdf-convert/tasks.html, chunk 1 of 3 0.747 specs/065-corpus-pdf-convert/design.html, chunk 1 of 5 0.720 specs/065-corpus-pdf-convert/spec.html, chunk 1 of 4 0.720 specs/065-corpus-pdf-convert/triage-log.html, chunk 1 of 4
A27: G-026 | B27: identifier | D27: What does FR-003 of spec 103, content budgets, say about checking a budget? | E27: A budget must be treated as a design constraint and must not be checked against any running text, because the real copy lives in systems the vocabulary cannot see. | F27: FR-003 of spec 103, content budgets, states that a budget is never checked against running text, because the copy resides in a localisation system or a person's draft. FR-003 forbids a check rather than requiring one, and an assertion is used to prevent it from being added later. | G27: correct | H27: A budget is never checked against running text; FR-003 forbids the check. | M27: =IF(I27="",G27&"",I27) -> correct | N27: =IF(K27="",J27&"",IF(K27="no","",K27)) | O27: miss: right file, other chunks | P27: Q1 (specs/103-content-budgets/design.html, chunk 1 of 3): The load-bearing decision is a refusal: a budget is never checked against running text, because the copy lives in a localisation system or a person's draft and a check that read only what it could reach would report clean while the rest overflowed. Q2 (specs/103-content-budgets/tasks.html, chunk 1 of 2): Assert nothing is ever checked against running text — a test that pins a refusal, since FR-003 forbids a check rather than requiring one and only an assertion stops it being added later. | Q27: A budget MUST be treated as a design constraint and MUST NOT be checked against any running text. | R27: specs/103-content-budgets/spec.html#FR-003 | S27: 0.768 specs/103-content-budgets/design.html, chunk 1 of 3 0.736 specs/103-content-budgets/verify.html, chunk 1 of 1 0.728 specs/103-content-budgets/tasks.html, chunk 1 of 2 0.710 specs/103-content-budgets/spec.html, chunk 1 of 3
A28: G-027 | B28: identifier | D28: What is decision D-001 in the design for spec 078, the federated resource URI? | E28: The corpus kind joins the existing shared composer: extend ResourceKind with 'corpus', add a thin named wrapper, and add an optional edition parameter emitted as ?edition= before any fragment. | F28: Decision D-001 in the design for spec 078, the federated resource URI, is referenced in P-3 as the application of FR-012 to uphold the coordinate as an id contract. | G28: wrong | H28: Talks about P-3 and FR-012; not what D-001 decides (corpus joins the shared composer). | M28: =IF(I28="",G28&"",I28) -> wrong | N28: =IF(K28="",J28&"",IF(K28="no","",K28)) | O28: miss: right file, other chunks | P28: Q1 (specs/078-federated-resource-uri/design.html, chunk 1 of 7): P-1 · Source order is reading order OK No artifact rendering changes. Q2 (specs/078-federated-resource-uri/design.html, chunk 1 of 7): P-3 · IDs are contracts OK Directly upheld — the coordinate is an id contract, and FR-012 forbids changing existing spec/contract output. D-004 is that clause applied. | Q28: Extend ResourceKind with 'corpus' and add a thin named wrapper beside the existing spec and contract wrappers. Add an optional edition parameter to the shared composer, emitted as ?edition= before any fragment. | R28: specs/078-federated-resource-uri/design.html#D-001 | S28: 0.751 specs/078-federated-resource-uri/design.html, chunk 1 of 7 0.710 specs/078-federated-resource-uri/design.html, chunk 7 of 7 0.695 specs/078-federated-resource-uri/verify.html, chunk 1 of 1 0.675 specs/078-federated-resource-uri/spec.html, chunk 1 of 6
A29: G-028 | B29: identifier | D29: What is success criterion SC-001 of spec 100, screen flows? | E29: For a feature declaring a journey, a reader can state the order of its screens and the failure branch of each step from the declaration alone, opening 0 other files. | F29: Success criterion SC-001 of spec 100, screen flows requires acceptance proof through tests T-100 to T-106. | G29: wrong | H29: Quotes 108's verify page about tests T-100 to T-106; not spec 100's SC-001. | M29: =IF(I29="",G29&"",I29) -> wrong | N29: =IF(K29="",J29&"",IF(K29="no","",K29)) | O29: miss: right file, other chunks | P29: Q1 (specs/108-success-criteria/verify.html, chunk 1 of 1): Success criterion Acceptance Proof (tests) SC-001 US1 T-100, T-101, T-102, T-103, T-104, T-105, T-106 | Q29: For a feature declaring a journey, a reader can state the order of its screens and the failure branch of each step from the declaration alone, opening 0 other files. | R29: specs/100-screen-flows/spec.html#SC-001 | S29: 0.709 specs/100-screen-flows/verify.html, chunk 1 of 1 0.680 specs/108-success-criteria/design.html, chunk 1 of 7 0.678 specs/108-success-criteria/verify.html, chunk 1 of 1 0.676 specs/100-screen-flows/spec.html, chunk 1 of 4
A30: G-029 | B30: relation | D30: Which success criteria in spec 109, the prose theme, validate FR-008 (the receding sticky header)? | E30: Two: SC-003 (keyboard readers reach every control the receding header carries, 100%) and SC-001 (reviewers read a long artifact end to end in one sitting); both list FR-008 in their validates attribute. | F30: FR-008, the receding sticky header, is validated by the rationale in FR-009 which scopes the sticky, backdrop-blurred header to vivid only, resolving the P-5 calm-density tension. The amendment in P-5 (calm density) is referenced as a check, not a blocker, which aligns with the validation of FR-008 through the calm-density tension resolution. | G30: wrong | H30: Answers from 016's triage log about FR-009; never names SC-001 or SC-003. | M30: =IF(I30="",G30&"",I30) -> wrong | N30: =IF(K30="",J30&"",IF(K30="no","",K30)) | O30: miss: another spec | P30: Q1 (specs/016-theme-support/triage-log.html, chunk 2 of 10): The amendment should confirm vivid still honours P-5 (calm density) — the reference reads as calm-but-dense, so this is a check, not a blocker. Q2 (specs/016-theme-support/triage-log.html, chunk 6 of 10): Spec upstream "We should also have the sticky header in calm" reads like a quick CSS toggle, but FR-009 deliberately scopes the sticky, backdrop-blurred header to vivid only — its rationale states this resolves the P-5 calm-density tension ("calm keeps its minimal chrome … calm has no header"). | Q30: Readers navigating by keyboard reach every control the receding header carries — share reachable 100% (target 100%), from no established baseline. | R30: specs/109-prose-theme/spec.html#SC-003 specs/109-prose-theme/spec.html#SC-001 | S30: 0.743 specs/016-theme-support/triage-log.html, chunk 2 of 10 0.738 specs/016-theme-support/triage-log.html, chunk 6 of 10 0.735 specs/016-theme-support/triage-log.html, chunk 10 of 10 0.734 specs/108-success-criteria/design.html, chunk 1 of 7
A31: G-030 | B31: relation | D31: Which requirements does success criterion SC-002 of spec 110, visual one-step, validate, and what do they demand? | E31: FR-003 and NFR-001: before any model call or file write, the invocation must refuse when the named export cannot be read and name the path; a refusing run makes 0 model calls and writes 0 files. | F31: Success criterion SC-002 of spec 110, visual one-step, validates the requirement to 'land the visuals in one step'. This requirement demands a method to run, demo, and verify the feature, with a Run/Demo block grounded in an actual run. | G31: wrong | H31: Never names FR-003 or NFR-001. | M31: =IF(I31="",G31&"",I31) -> wrong | N31: =IF(K31="",J31&"",IF(K31="no","",K31)) | O31: miss: right spec, other pages | P31: Q1 (specs/110-visual-one-step/verify.html, chunk 1 of 1): Verify · 110-visual-one-step Land the visuals in one step How to run, demo, and verify this feature — aggregated from the spec and tasks, with a Run/Demo block grounded in the run that actually happened. | Q31: Before making any model call and before writing any file, the invocation MUST refuse when the named export cannot be read, and MUST state which path it could not read. | R31: specs/110-visual-one-step/spec.html#FR-003 specs/110-visual-one-step/spec.html#NFR-001 | S31: 0.774 specs/108-success-criteria/verify.html, chunk 1 of 1 0.760 specs/110-visual-one-step/verify.html, chunk 1 of 1 0.752 specs/108-success-criteria/design.html, chunk 1 of 7 0.733 specs/110-visual-one-step/triage-log.html, chunk 1 of 4
A32: G-031 | B32: relation | D32: Spec 058's corpus-license rule reads a license field that 058 says it does not own. Which spec defines that field, and what else goes in that frontmatter? | E32: 051-knowledge-corpus (FR-003): every corpus document carries provenance frontmatter of origin/origin-url, edition, license, converter, a content hash and a status. | F32: Spec 058's corpus-license rule references a license field that it does not own, as per the design document. The field in question is defined by the corpus-licensing spec, which includes a permissive allowlist and a written policy for escape hatches. | G32: wrong | H32: Says 058 itself defines the field; it is 051 FR-003. | M32: =IF(I32="",G32&"",I32) -> wrong | N32: =IF(K32="",J32&"",IF(K32="no","",K32)) | O32: miss: right spec, other pages | P32: Q1 (specs/058-corpus-licensing/design.html, chunk 1 of 6): Design · 058-corpus-licensing Corpus licensing One folded validate rule that classifies a declared license against a permissive allowlist — surfacing everything else, never adjudicating any of it — plus a written policy that names the escape hatch. | Q32: Every corpus document MUST carry provenance frontmatter: origin / origin-url , edition , license , converter , a content hash, and a status (e.g. illustrative-excerpt vs authoritative). | R32: specs/051-knowledge-corpus/spec.html#FR-003 specs/058-corpus-licensing/spec.html#requirements | S32: 0.785 specs/058-corpus-licensing/design.html, chunk 4 of 6 0.784 specs/058-corpus-licensing/design.html, chunk 1 of 6 0.774 specs/058-corpus-licensing/design.html, chunk 6 of 6 0.772 specs/058-corpus-licensing/tasks.html, chunk 1 of 2
A33: G-032 | B33: relation | D33: Spec 055 (corpus in review) leaves injecting the corpus into the authoring verbs out of scope. Which spec handles that, and what does it require? | E33: 054-corpus-in-prompt: when a corpus is present, core must inject its index and a grounding directive into every AI-verb prompt, using the same fenced mechanism that injects the principles. | F33: Spec 055 (corpus in review) does not include injecting the corpus into the authoring verbs. The requirement for injecting the corpus into the authoring verbs is addressed in another specification, though the exact reference is not provided in the quoted text. | G33: wrong | H33: Says another spec handles it but cannot say which; 054 was never retrieved. | M33: =IF(I33="",G33&"",I33) -> wrong | N33: =IF(K33="",J33&"",IF(K33="no","",K33)) | O33: miss: right file, other chunks | P33: Q1 (specs/055-corpus-in-review/design.html, chunk 1 of 5): The guarantee is presence; use stays advisory. Status Accepted Spec 055-corpus-in-review Owner Brian Corbin · @briancorbinxyz Branch main Created 25 Jul 2026 Read time 054 already places the fenced corpus in the core critic's reviewPrompt, but with an authoring directive; | Q33: When a corpus is present, core MUST inject its index and a grounding directive into every AI-verb prompt, via the same fenced mechanism that already injects the principles. | R33: specs/054-corpus-in-prompt/spec.html#FR-001 specs/055-corpus-in-review/spec.html#requirements | S33: 0.803 specs/055-corpus-in-review/design.html, chunk 1 of 5 0.797 specs/055-corpus-in-review/tasks.html, chunk 1 of 3 0.794 specs/055-corpus-in-review/spec.html, chunk 1 of 3 0.778 specs/055-corpus-in-review/verify.html, chunk 1 of 1
A34: G-033 | B34: relation | D34: Spec 023's design dropped its decision on generating restore tasks after an exploration graduates. Which slice took that over, and how is restore invoked now? | E34: It moved to the sibling slice TBD-explore-restore, now 024-explore-restore, where restore is a mode of /spectastic.tasks: /spectastic.tasks <id> --restore, or an announced prompt when a graduated marker is present. | F34: Spec 023's decision to generate restore tasks was split out into a separate slice, 024-explore-restore. The restore path is now invoked explicitly via a --restore flag or an announced prompt, and the output is banner-labelled with its classification. | G34: correct | H34: Moved to 024-explore-restore; restore via --restore or an announced prompt. | M34: =IF(I34="",G34&"",I34) -> correct | N34: =IF(K34="",J34&"",IF(K34="no","",K34)) | O34: miss: right file, other chunks | P34: Q1 (specs/024-explore-restore/spec.html, chunk 1 of 3): Specification · 024-explore-restore explore restore — refactor or rebuild a graduated build to spec The restore half of graduation, split out of 023: /spectastic.tasks <id> --restore turns a graduated spec + plan into a path-appropriate tasks.html — refactor-to-comply for a tracer-bullet, clean-rebuild for a spike — reading the frozen classification, test-first either way. Q2 (specs/024-explore-restore/spec.html, chunk 1 of 3): The restore path is always explicit — a --restore flag or an announced prompt — never a silent branch, and the output is banner-labelled with its classification. | Q34: US2 (restore-scaffold) was split to the sibling slice TBD-explore-restore when 023's budget went red (the spec's INVEST·Small trigger). | R34: specs/023-explore-graduation/design.html#D-006 specs/024-explore-restore/spec.html#FR-001 | S34: 0.809 specs/024-explore-restore/spec.html, chunk 1 of 3 0.792 specs/024-explore-restore/spec.html, chunk 3 of 3 0.787 specs/024-explore-restore/tasks.html, chunk 1 of 2 0.768 specs/024-explore-restore/design.html, chunk 1 of 4
A35: G-034 | B35: relation | D35: Which spec superseded 001-cli, and what did it require happen to the old Python CLI? | E35: 003-init-node-port: at its apply, scripts/spectastic and scripts/test_spectastic.py were removed and 001-cli's status flipped to superseded with a forward link to 003; 001 stays as historical record. | F35: Spec 001-cli was superseded by 003-init-node-port on 15 Jun 2026. The old Python CLI described in 001-cli was deleted from the repo, and spectastic init now lives as a subcommand of @spectastic/cli. | G35: correct | H35: Superseded by 003-init-node-port; the Python CLI was deleted. | M35: =IF(I35="",G35&"",I35) -> correct | N35: =IF(K35="",J35&"",IF(K35="no","",K35)) | O35: miss: right spec, other pages | P35: Q1 (specs/001-cli/spec.html, chunk 1 of 3): Superseded by 003-init-node-port on 15 Jun 2026. The Python single-file CLI described below has been deleted from the repo; spectastic init now lives as a subcommand of @spectastic/cli. Q2 (specs/003-init-node-port/tasks.html, chunk 3 of 4): SC-003 Post-apply: no Python; 001-cli superseded T-901, T-902, T-903, T-906 | Q35: the Python script scripts/spectastic and its test file scripts/test_spectastic.py MUST be removed from the repository, and spec 001-cli 's <spec-status> MUST flip to superseded with a forward link to this spec. | R35: specs/003-init-node-port/spec.html#FR-010 | S35: 0.806 specs/003-init-node-port/tasks.html, chunk 3 of 4 0.719 specs/001-cli/design.html, chunk 1 of 3 0.710 specs/001-cli/spec.html, chunk 1 of 3 0.708 specs/000-spectastic/changes/archive/2026-06-15-lifecycle-state-transitions/proposal.html, chunk 2 of 4
